Workbook

Sheet JAN - MARCH Expired
A1: Seller ID | B1: Store Name | C1: Date of Onboarding | D1: Team | E1: AM | F1: Priority | G1: Connected for Retention | H1: Tool Demo Completed | I1: Demo Date | J1: Follow - Ups | K1: Last FollowUp Date | L1: Intent | M1: Payment Link Sent | N1: Payment link Sent Date | O1: Amount Pitched | P1: Duration Pitched | Q1: Closure | R1: Closure Date | S1: Closure Amount | T1: Remark
A2: A3EE777HLJWZLM | B2: MAOU STORES - IN | C2: 45669 | D2: POD-Chamath | E2: Gourav Haldar | F2: P2
A3: A1DC0MJDFCP1BU | B3: S M R CHIPS N SNACKS LLP - IN | C3: 45700 | D3: POD-Chamath | E3: Gourav Haldar | F3: P2
A4: A2VW28JRMUPD94 | B4: Newway_lifestyles - IN | C4: 45700 | D4: POD-Chamath | E4: Gourav Haldar | F4: P1
A5: A3QGGG0VSGF8ZH | B5: LAYBARE INTERNATIONAL PRIVATE LIMITED - IN | C5: 45700 | D5: POD-Chamath | E5: Gourav Haldar | F5: P2
A6: A1JAI4TO86VEX | B6: Giftkidukan - IN | C6: 45700 | D6: POD-Chamath | E6: Gourav Haldar | F6: P3
A7: A2AB5ZVYS9TOYU | B7: VJ ENTERPRISESÂ® - IN | C7: 45700 | D7: POD-Chamath | E7: Gourav Haldar | F7: P3
A8: A24ZBAKBTZ74G5 | B8: SHOAIB ANSARI - IN | C8: 45727 | D8: POD-Chamath | E8: Gourav Haldar | F8: P2
A9: A1MMVW7J08Y4AV | B9: AURA ENTERPRISE. - IN | C9: 45788 | D9: POD-Chamath | E9: Gourav Haldar | F9: P2
A10: AO4JD9W0THSG8 | B10: PN SHOPS - IN | C10: 45788 | D10: POD-Chamath | E10: Gourav Haldar | F10: P2
A11: A16T8VRIV4CL8M | B11: FoxHill - IN | C11: 45788 | D11: POD-Chamath | E11: Gourav Haldar | F11: P1
A12: A3B4LIBTDDBYGV | B12: OREEN INTERNATIONAL PRIVATE LIMITED - IN | C12: 45788 | D12: POD-Chamath | E12: Gourav Haldar | F12: P2
A13: A3R29YN2SXLHYE | B13: Doshi Enterprises Mumbai - IN | C13: 45789 | D13: POD-Chamath | E13: Gourav Haldar | F13: P2
... A37: A1EG65MGJDGRYK | B37: VINIYOG INDUSTRIES PRIVATE LIMITED - IN | C37: 46054 | D37: POD-Chamath | E37: Gourav Haldar | F37: P2
A38: A10LQCSQUUT9AJ | B38: BLISSFLAIR - IN | C38: 11/13/2025 | D38: POD-Chamath | E38: Gourav Haldar | F38: P3
A39: A1UJLBMXY4PGOI | B39: LIBAUM - IN | C39: 11/13/2025 | D39: POD-Chamath | E39: Gourav Haldar | F39: P1
A40: A1SIIOGJNV4GP1 | B40: SOMNATH ENTERPRISE (Tiny Treasure) - IN | C40: 11/13/2025 | D40: POD-Chamath | E40: Gourav Haldar | F40: P3
A41: A34ULRVXDWSDYV | B41: ANITABEN JAYESHBHAI KAKADIYA - IN | C41: 11/13/2025 | D41: POD-Chamath | E41: Gourav Haldar | F41: P2
A42: A38YCKN409XHLF | B42: Adisesh Overseas - IN | C42: 11/13/2025 | D42: POD-Chamath | E42: Gourav Haldar | F42: P2
A43: A3JCQE8JZOI17J | B43: Veer Vachhraj Enterprise - IN | C43: 11/13/2025 | D43: POD-Chamath | E43: Gourav Haldar | F43: P1
A44: A3AUGRDF0HKV39 | B44: FOOZ GLOBAL LLP - IN | C44: 11/14/2025 | D44: POD-Chamath | E44: Gourav Haldar | F44: P2
A45: A1STWPS3AJFT5H | B45: M/S. ASSAL AMRAVATI MH 27 / NAYAN MUKUNDRAO KUDALE - IN | C45: 11/14/2025 | D45: POD-Chamath | E45: Gourav Haldar | F45: P3
A46: A157FFHHY9O5C0 | B46: KOMFY APPARELS PRIVATE LIMITED - IN | C46: 11/14/2025 | D46: POD-Chamath | E46: Gourav Haldar | F46: P3
A47: A1EULY3250XC1L | B47: Firox X - IN | C47: 11/14/2025 | D47: POD-Chamath | E47: Gourav Haldar | F47: P1
A48: A37SC2QC5GAUSY | B48: Karcari Products LLP - IN | C48: 11/16/2025 | D48: POD-Chamath | E48: Gourav Haldar | F48: P3
A49: AP7K3VMVVLLV9 | B49: ADVI INTERNATIONAL PRIVATE LIMITED - IN | C49: 11/17/2025 | D49: POD-Chamath | E49: Gourav Haldar | F49: P2
... A123: A2L9KY1PFIO5GU | B123: APEX LED PRODUCTS - IN | C123: 12/30/2025 | D123: POD-Chamath | E123: Gourav Haldar | F123: P3
A124: A1JCZ5K9A866O8 | B124: Roscoe - IN | C124: 45669 | D124: POD-Sanjay | E124: Moupali Mitra | F124: P0
A125: A2SRWKDNJJ3YIK | B125: Extend Pvt.Ltd. - IN | C125: 45669 | D125: POD-Sanjay | E125: Moupali Mitra | F125: P3
A126: A1H0KFN7FXRKHO | B126: INDIAN ART INDUSTRIES - IN | C126: 45669 | D126: POD-Sanjay | E126: Moupali Mitra | F126: P3
A127: A1JKDYTBMTZ6L6 | B127: Nature Agro - IN | C127: 45669 | D127: POD-Sanjay | E127: Moupali Mitra | F127: P2
A128: ABPLVCU27BF3P | B128: RUDRART CREATIONS - IN | C128: 45669 | D128: POD-Sanjay | E128: Moupali Mitra | F128: P3
A129: A16W0FSUAXS6QP | B129: Kalp Controls - IN | C129: 45669 | D129: POD-Sanjay | E129: Moupali Mitra | F129: P2
A130: A2IQFNC7X1VUNP | B130: LAVANYA ENTERPRISES Products - IN | C130: 45669 | D130: POD-Sanjay | E130: Moupali Mitra | F130: P2
A131: A3CPS5IWA6VMAQ | B131: NOVIQ ENTERPRISES - IN | C131: 45700 | D131: POD-Sanjay | E131: Moupali Mitra | F131: P1
A132: A1TSSDVIQ076I7 | B132: NS Enterprises & Traders - IN | C132: 45700 | D132: POD-Sanjay | E132: Moupali Mitra | F132: P2
A133: A1KRK73P2YNR4L | B133: Total ortho care - IN | C133: 45700 | D133: POD-Sanjay | E133: Moupali Mitra | F133: P2
A134: A6Y77M7QC8HMA | B134: Bareilly Cane Furniture - IN | C134: 45700 | D134: POD-Sanjay | E134: Moupali Mitra | F134: P1
A135: A2UGHR7YUFBCGN | B135: Shri Salasar enterprisess - IN | C135: 45727 | D135: POD-Sanjay | E135: Moupali Mitra | F135: P2
... A163: A1DR6SHA473KXO | B163: krishav Enterprises - IN | C163: 45972 | D163: POD-Sanjay | E163: Moupali Mitra | F163: P3
...

Sheet APRIL Expired
A1: Seller ID | B1: Store Name | C1: Date of Onboarding | D1: Team | E1: AM | F1: Priority | G1: Connected for Retention | H1: Tool Demo Completed | I1: Demo Date | J1: Follow - Ups | K1: Last FollowUp Date | L1: Intent | M1: Payment Link Sent | N1: Payment link Sent Date | O1: Amount Pitched | P1: Duration Pitched | Q1: Closure | R1: Closure Date | S1: Closure Amount | T1: Remark
A2: A2B2SMMINF1I0J | B2: VYAPAK CREATION - IN | C2: 46079 | D2: POD-Chamath | E2: Chamanth | F2: P2 | G2: Yes | H2: Yes
A3: AUGAI74W2GP8U | B3: IMPERSE - IN | C3: 46069 | D3: POD-Chamath | E3: Chamanth | F3: P2 | G3: No | H3: No
A4: A1R2WCNCQWX195 | B4: BNCollectionl - IN | C4: 46069 | D4: POD-Chamath | E4: Chamanth | F4: P2 | G4: Yes | H4: Yes | I4: 46136 | J4: 1 | K4: 46142 | L4: Not Interested | T4: Not intrested right now
A5: AF21KKQWKOKUD | B5: Chicmik - IN | C5: 46070 | D5: POD-Chamath | E5: Chamanth | F5: P2 | G5: No | H5: No | I5: 46142 | J5: 1 | K5: 46142 | L5: Not Interested | T5: Not working on the store now, closing the amazon store
A6: A3HXYZ30I3V222 | B6: SKSI - IN | C6: 46080 | D6: POD-Chamath | E6: Chamanth | F6: P0 | G6: Yes | H6: Yes | I6: 46127 | J6: 4 | K6: 46142 | L6: Interested | M6: No | O6: 120000 | P6: 12 Months | Q6: Yes | T6: Amount pitched for 2 accounts
A7: A26O2NN29RXS5M | B7: Saforia India - IN | C7: 46080 | D7: POD-Chamath | E7: Chamanth | F7: P2 | G7: Yes | H7: Yes | I7: 46136 | J7: 1 | K7: 46142 | L7: In Piepline | T7: Owner told have given to an agnecy/ told to call back on tuesday 5th may
A8: A32W2AGRL3ORZO | B8: Umera Handicrafts - IN | C8: 46077 | D8: POD-Chamath | E8: Chamanth | F8: P2 | G8: No | H8: No | K8: 46142 | T8: RNR
A9: A3DCV8IRCCFI5E | B9: URJA ENTERPRISE - IN | C9: 46081 | D9: POD-Chamath | E9: Chamanth | F9: P2 | G9: Yes | H9: Yes | I9: 46118 | J9: 1 | K9: 46142 | L9: Not Interested
A10: A9HOHOEKNR58K | B10: Yash&Company - IN | C10: 46081 | D10: POD-Chamath | E10: Chamanth | F10: P2 | G10: No | H10: No
A11: AYBKLUENUJB4B | B11: .Prime Enterprises - IN | C11: 46071 | D11: POD-Chamath | E11: Chamanth | F11: P2 | G11: Yes | H11: No | I11: 46142 | J11: 1 | K11: 46142 | L11: Not Interested | T11: Not intrested, wanted to manuaaly handel
A12: A23MQ7T2PFWL6V | B12: Pramukh Saless.. - IN | C12: 46066 | D12: POD-Chamath | E12: Chamanth | F12: P2 | G12: Yes | H12: Yes | I12: 46142 | J12: 2 | K12: 46142 | L12: Not Interested
A13: A20I5QDK4MHR3U | B13: PrathaVastra - IN | C13: 46066 | D13: POD-Chamath | E13: Chamanth | F13: P1 | G13: Yes | H13: No | I13: 46142 | K13: 46142 | L13: Interested | O13: 25000 | P13: 3 Months | T13: asked to schedule a meet at 3pm
A14: A2O0GM6T86JYJB | B14: NATIONAL REFRIGERATION HOUSE - IN | C14: 46077 | D14: POD-Sanjay | E14: Saikumar | F14: P2 | G14: No | H14: No | T14: Disconnected
A15: A3TV37UEYXQM9O | B15: Nutrafloat - IN | C15: 46055 | D15: POD-Sanjay | E15: Saikumar | F15: P3 | G15: No | H15: No | T15: Disconnected
A16: A1RG8P5ZBBI73Q | B16: R.R-FASHION - IN | C16: 46077 | D16: POD-Sanjay | E16: Saikumar | F16: P1 | G16: Yes | H16: No | L16: Not Interested
A17: AI60Y4RK9JWJY | B17: BLUECOLOGNE NATURALS - IN | C17: 46064 | D17: POD-Sanjay | E17: Saikumar | F17: P3 | G17: Yes | H17: No | L17: Not Interested
A18: A24M12VKMXP0HK | B18: King Mart Enterprises - IN | C18: 46076 | D18: POD-Sanjay | E18: Saikumar | F18: P3 | G18: Yes | H18: No | L18: Not Interested
A19: A3S6D67WGD48DG | B19: Advance Engineering Works! - IN | C19: 46069 | D19: POD-Sanjay | E19: Saikumar | F19: P2 | G19: No | H19: No | T19: Listing Issue
A20: A2DFGRZE4GOL8G | B20: AstroDevam Pvt. Ltd - IN | C20: 46069 | D20: POD-Sanjay | E20: Saikumar | F20: P2 | G20: Yes | H20: Yes | I20: 46112 | J20: 3 | K20: 46140 | L20: Interested
A21: A289JL7QAZDRGE | B21: FARM 2 FACTORY - IN | C21: 46063 | D21: POD-Sanjay | E21: Saikumar | F21: P2 | G21: Yes | H21: No | L21: Not Interested
A22: A3LZAHNPV3G1FU | B22: LE SHOPPING CART - IN | C22: 46079 | D22: POD-Sanjay | E22: Saikumar | F22: P2 | G22: No | H22: No | T22: Disconnected
A23: A1TU3MDB47YLZK | B23: PERONICA FASHION - IN | C23: 46069 | D23: POD-Sanjay | E23: Saikumar | F23: P3 | G23: Yes | H23: No | L23: Not Interested
A24: A3PSDIUKRZLGSJ | B24: RAINBOW PAPER PRODUCTS - IN | C24: 46063 | D24: POD-Sanjay | E24: Saikumar | F24: P2 | G24: Yes | H24: Yes | I24: 46114 | J24: 4 | K24: 46140 | L24: In Piepline
A25: A2OR5TMZ6DJGKE | B25: RAMDUT ENTERPRISE.. - IN | C25: 46069 | D25: POD-Sanjay | E25: Saikumar | F25: P2 | G25: Yes | H25: No | L25: Not Interested
A26: A3JB2SIKAFSX4W | B26: ROSAMODE - IN | C26: 46055 | D26: POD-Sanjay | E26: Saikumar | F26: P3 | G26: Yes | H26: No | L26: Not Interested
A27: A1TPM9HK5HK577 | B27: Rk kaime sports - IN | C27: 46070 | D27: POD-Sanjay | E27: Saikumar | F27: P2 | G27: No | H27: No
A28: A1H5QICWWAILR4 | B28: SPIRY MALL - IN | C28: 46069 | D28: POD-Sanjay | E28: Saikumar | F28: P1 | G28: Yes | H28: No | L28: In Piepline
A29: A2N9CVT8WE5J8T | B29: THE ALPINE APOTHECARY - IN | C29: 46063 | D29: POD-Sanjay | E29: Saikumar | F29: P1 | G29: Yes | H29: Yes | I29: 46135 | L29: Not Interested
A30: A1ZNJW3WTUDRNM | B30: Textile Now - IN | C30: 46070 | D30: POD-Sanjay | E30: Saikumar | F30: P3 | G30: Yes | H30: No | L30: Not Interested
A31: A27KU97V00LDVG | B31: Tinkle. - IN | C31: 46077 | D31: POD-Sanjay | E31: Saikumar | F31: P2 | G31: Yes | H31: Yes | I31: 46136 | J31: 4 | K31: 46139 | L31: Interested | O31: 8500 | P31: 1 Months
A32: A3BLAJMVTEVJOO | B32: Viewstar Future Retail Private Limited - IN | C32: 46076 | D32: POD-Sanjay | E32: Saikumar | F32: P1 | G32: No | H32: No | T32: Disconnected
A33: A1JZUR4EAD3T2T | B33: Virva enterprise - IN | C33: 46079 | D33: POD-Sanjay | E33: Saikumar | F33: P1 | G33: Yes | H33: No | L33: Not Interested
A34: A370SOFCJP9R6F | B34: WALLAURA - IN | C34: 46077 | D34: POD-Sanjay | E34: Saikumar | F34: P3 | G34: No | H34: No | T34: Disconnected
A35: A4XCDBYFHYQ93 | B35: Yug Ecom - IN | C35: 46079 | D35: POD-Sanjay | E35: Saikumar | F35: P2 | G35: Yes | H35: No | L35: Not Interested
A36: A1HN7U8DB740X2 | B36: GURU JEE - IN | C36: 46080 | D36: POD-Sanjay | E36: Saikumar | F36: P2 | G36: Yes | H36: No | L36: Not Interested
A37: A3CFRSVJU25LG8 | B37: WE CARE 4 U - IN | C37: 46080 | D37: POD-Sanjay | E37: Saikumar | F37: P2 | G37: Yes | H37: Yes | I37: 46139 | J37: 1 | K37: 46139 | L37: Interested | O37: 30000 | P37: 3 Months
A38: AC7HI0LJQ7J46 | B38: Angoori Fashion - IN | C38: 46057 | D38: POD-Sanjay | E38: Saikumar | F38: P1 | G38: Yes | H38: Yes | I38: 46121 | J38: 2 | K38: 46140 | L38: Not Interested | O38: 25000 | P38: 3 Months
A39: ATO617QMILZUL | B39: GATIMAN COLLECTION - IN | C39: 46057 | D39: POD-Sanjay | E39: Saikumar | F39: P1 | G39: Yes | H39: Yes | I39: 46097 | J39: 5 | K39: 46139 | L39: Interested | O39: 80000 | P39: 12 Months
A40: A3AX28MEOT54PY | B40: Aakash Trader's - IN | C40: 46065 | D40: POD-Sanjay | E40: Saikumar | F40: P2 | G40: Yes | H40: No | L40: Not Interested
...

Sheet MAY Expired
A1: Seller ID | B1: Store Name | C1: Date of Onboarding | D1: Team | E1: AM | F1: Priority | G1: Connected for Retention | H1: Tool Demo Completed | I1: Demo Date | J1: Follow - Ups | K1: Last FollowUp Date | L1: Intent | M1: Payment Link Sent | N1: Payment link Sent Date | O1: Amount Pitched | P1: Duration Pitched | Q1: Closure | R1: Closure Date | S1: Closure Amount | T1: Remark
A2: A2810Y9W7CXMNM | B2: assortify - IN | C2: 3/27/2026 | D2: POD-Sanjay | E2: Anurag Rathore | F2: P2
A3: A22GDTQWACDK8U | B3: The Watch Company.. - IN | C3: 3/27/2026 | D3: POD-Sanjay | E3: Anurag Rathore | F3: P1
A4: AU33UEHGJ22NS | B4: GROWTH EMPIREâ„¢ - IN | C4: 3/27/2026 | D4: POD-Sanjay | E4: Palakh Jain | F4: P2
A5: A8KQ1ZO6YGS7J | B5: Bengal HandlOom Saree - IN | C5: 3/27/2026 | D5: POD-Sanjay | E5: Palakh Jain | F5: P2
A6: A31AMSHB0581A1 | B6: CZTL - IN | C6: 3/27/2026 | D6: POD-Sanjay | E6: Palakh Jain | F6: P3
A7: A3L43QR8BW3K3A | B7: SREE SAI ROLLER FLOUR MILL - IN | C7: 3/25/2026 | D7: POD-Chamath | E7: Ved Prakash Kondaboiena | F7: P2
A8: A136LAAXUJA72D | B8: HENLYS SUNS - IN | C8: 3/24/2026 | D8: POD-Sanjay | E8: Palakh Jain | F8: P1
A9: A1M0V5H9R1Y258 | B9: KLYNEST ENTERPRISE - IN | C9: 3/24/2026 | D9: POD-Sanjay | E9: Palakh Jain | F9: P2
A10: A1XM5WNED436ZW | B10: DIVYA METAL CRAFTS - IN | C10: 3/24/2026 | D10: POD-Sanjay | E10: Palakh Jain | F10: P2
A11: A3VRWFD2FUG66 | B11: SHREE SAI ENTERPRISES01 - IN | C11: 3/24/2026 | D11: POD-Sanjay | E11: Sanjay | F11: P3
A12: A1SU3SF254UYYD | B12: R G WOOD - IN | C12: 3/24/2026 | D12: POD-Chamath | E12: Ved Prakash Kondaboiena | F12: P3
A13: A1JPF25BQOQBI0 | B13: KIDSGALLERY - IN | C13: 3/24/2026 | D13: POD-Chamath | E13: Ved Prakash Kondaboiena | F13: P2
... A51: AGTUD2QY0829G | B51: ANTALYAâ„¢ - IN | C51: 3/13/2026 | D51: POD-Chamath | E51: Ved Prakash Kondaboiena | F51: P2
A52: A3DF8ZQ7HKH115 | B52: HARIVAR - IN | C52: 46359 | D52: POD-Chamath | E52: Sarthak Gophane | F52: P1
A53: A31RS44GEFNAZ | B53: tee mafia - IN | C53: 46359 | D53: POD-Chamath | E53: Sarthak Gophane | F53: P2
A54: A1MOMTYYK4NALS | B54: Rakhi Saini - IN | C54: 46359 | D54: POD-Chamath | E54: Sarthak Gophane | F54: P2
A55: A1T4DZOACRNFXP | B55: VIKASH TOY CENTRE PRIVATE LIMITED - IN | C55: 46359 | D55: POD-Chamath | E55: Sarthak Gophane | F55: P1
A56: A35TA87GIQ77SX | B56: kuldip patel - IN | C56: 46359 | D56: POD-Chamath | E56: Sarthak Gophane | F56: P1
A57: A2SHU3SQWUE861 | B57: R.K. Textiles FAB - IN | C57: 46359 | D57: POD-Chamath | E57: Sarthak Gophane | F57: P1
A58: AG4VS7OLXCDSV | B58: RESDEK - IN | C58: 46359 | D58: POD-Chamath | E58: Sarthak Gophane | F58: P2
A59: A29Q3YV2MG0RPA | B59: NLH ROOTS - IN | C59: 46359 | D59: POD-Chamath | E59: Sarthak Gophane | F59: P1
A60: A1H79SGAGV52P1 | B60: Ayush Pharmaceuticals and Marketing Division - IN | C60: 46359 | D60: POD-Chamath | E60: Sarthak Gophane | F60: P3
A61: A1PXVKPUJ84ITP | B61: Renew Roots - IN | C61: 46359 | D61: POD-Sanjay | E61: Saikumar | F61: P2
A62: AG0RN0ZGIVPXU | B62: DBrush - IN | C62: 46359 | D62: POD-Sanjay | E62: Saikumar | F62: P2
A63: A258LXFA0FPNGT | B63: Emyra Enterprises - IN | C63: 46359 | D63: POD-Sanjay | E63: Saikumar | F63: P3
... A104: A2HIVSN5V4E776 | B104: RUDRA SAMRAT - IN | C104: 46056 | D104: POD-Chamath | E104: Sarthak Gophane | F104: P2

Sheet JUNE Expired
A1: Seller ID | B1: Store Name | C1: Date of Onboarding | D1: Team | E1: AM | F1: Priority | G1: Connected for Retention | H1: Tool Demo Completed | I1: Demo Date | J1: Follow - Ups | K1: Last FollowUp Date | L1: Intent | M1: Payment Link Sent | N1: Payment link Sent Date | O1: Amount Pitched | P1: Duration Pitched | Q1: Closure | R1: Closure Date | S1: Closure Amount | T1: Remark
A2: A2CVZ18N60T04H | B2: RITSAN COLLECTION - IN | C2: 4/30/2026 | D2: POD-Sanjay | E2: Palakh Jain | F2: P1
A3: A2FCEG0D4F2LTW | B3: GOAL ZONE - IN | C3: 4/30/2026 | D3: POD-Sanjay | E3: Palakh Jain | F3: P3
A4: A2IX705HS7SR2F | B4: Shopoflux - IN | C4: 4/30/2026 | D4: POD-Chamath | E4: Ved Prakash Kondaboiena | F4: P3
A5: AC4U8OCEA6G17 | B5: ROYAL DAIRY & SCIENTIFIC UDYOG. - IN | C5: 4/30/2026 | D5: POD-Chamath | E5: Ved Prakash Kondaboiena | F5: P2
A6: A2D6WWCD4RF124 | B6: MINALPRODUCTS - IN | C6: 4/29/2026 | D6: POD-Sanjay | E6: Palakh Jain | F6: P2
A7: AJS813TNES0IS | B7: Blooming collection - IN | C7: 4/29/2026 | D7: POD-Sanjay | E7: Palakh Jain | F7: P3
A8: A634F62XPKOZM | B8: NEW VIKAS LIGHT - IN | C8: 4/29/2026 | D8: POD-Sanjay | E8: Palakh Jain | F8: P2
A9: A2IHDGL4NZJV0M | B9: PinkLoom - IN | C9: 4/28/2026 | D9: POD-Chamath | E9: Sarthak Gophane | F9: P3
A10: A2M7DELZVSPJYK | B10: BHISRA HETSVEE SUDHIRBHAI - IN | C10: 4/28/2026 | D10: POD-Sanjay | E10: Anurag Rathore | F10: P2
A11: A39B1PQRTWRZSQ | B11: J J ENTERPRISE001 - IN | C11: 4/28/2026 | D11: POD-Sanjay | E11: Anurag Rathore | F11: P3
A12: A2MLDQV70U96CF | B12: Fiable Collection - IN | C12: 4/28/2026 | D12: POD-Sanjay | E12: Anurag Rathore | F12: P2
A13: A1R8M2HMSFJGYA | B13: MADHU TEXTILE JPR - IN | C13: 4/28/2026 | D13: POD-Sanjay | E13: Anurag Rathore | F13: P3
... A80: A2JOL8RJHF4UXW | B80: YVR FASHION PRIVATE LIMITED - IN | C80: 4/13/2026 | D80: POD-Chamath | E80: Ved Prakash Kondaboiena | F80: P2
A81: A1TKHYXDMZMXCK | B81: pn enterprise - IN | C81: 46207 | D81: POD-Sanjay | E81: Palakh Jain | F81: P2
A82: A2Q1QY73ICUV9Q | B82: BOOK CLOUD - IN | C82: 46207 | D82: POD-Sanjay | E82: Anurag Rathore | F82: P2
A83: A3IMUEXXSH9XKC | B83: Saiz Divine Wood - IN | C83: 46207 | D83: POD-Sanjay | E83: Palakh Jain | F83: P3
A84: A29MF1N2XOTX3N | B84: JS Clothing Mart - IN | C84: 46207 | D84: POD-Sanjay | E84: Palakh Jain | F84: P3
A85: A15ZO80XKO25MF | B85: SWAG ENTERPRISES - IN | C85: 46207 | D85: POD-Sanjay | E85: Palakh Jain | F85: P1
A86: AVNMWR2LBQP45 | B86: SETIA INTERNATIONAL - IN | C86: 46207 | D86: POD-Sanjay | E86: Palakh Jain | F86: P3
A87: A1X3YSKXWA3FC9 | B87: MOTI METAL INDUSTRIES - IN | C87: 46207 | D87: POD-Sanjay | E87: Palakh Jain | F87: P1
A88: AQOHGA4S43QDR | B88: E SALE RETAILERS - IN | C88: 46207 | D88: POD-Sanjay | E88: Anurag Rathore | F88: P1
A89: A39SGH88F1ESE2 | B89: ARRIYAN ARTS AND CRAFT - IN | C89: 46207 | D89: POD-Sanjay | E89: Anurag Rathore | F89: P1
A90: A4YAY7KEUHZX1 | B90: True Furniture - IN | C90: 46207 | D90: POD-Sanjay | E90: Palakh Jain | F90: P1
A91: A1K2D45RTCUS5H | B91: Bmtexture - IN | C91: 46207 | D91: POD-Sanjay | E91: Anurag Rathore | F91: P1
A92: A2RM69IJTGNTXB | B92: AMR ENTERPRISE - IN | C92: 46207 | D92: POD-Sanjay | E92: Anurag Rathore | F92: P1
... A98: AO6S0ATSG4V2X | B98: IKAE - IN | C98: 46026 | D98: POD-Sanjay | E98: Saikumar | F98: P1

Sheet 4+ CSAT
A1: Seller ID | B1: Store Name | C1: Bucket | D1: RATING | E1: AM | F1: Assigned To
A2: A1EB5K70GA1JL0 | B2: M/S FUR LOVED - IN | C2: PERFORMANCE + RAPO | D2: 4 | E2: =VLOOKUP(A2,'APRIL Expired'!A:E,4,FALSE) -> #N/A | F2: =VLOOKUP(A2,'APRIL Expired'!A:E,9,FALSE) -> #REF!
A3: A23LZVQIAFRU3J | B3: ACCUPRESSURE SHODH PRASHIKSHAN EVAM UPCHAR SANSTHAN - IN | C3: PERFORMANCE + RAPO | D3: 4 | E3: =VLOOKUP(A3,'APRIL Expired'!A:E,4,FALSE) -> #N/A | F3: =VLOOKUP(A3,'APRIL Expired'!A:E,9,FALSE) -> #REF!
A4: A2KSS3D61NYYNK | B4: SM ENTERPRISE Shoppe - IN | C4: PERFORMANCE + RAPO | D4: 4 | E4: =VLOOKUP(A4,'APRIL Expired'!A:E,4,FALSE) -> #N/A | F4: =VLOOKUP(A4,'APRIL Expired'!A:E,9,FALSE) -> #REF!
A5: ABI9V86KU74QT | B5: RS TRADING CORPORATION - IN | C5: PERFORMANCE + RAPO | D5: 4 | E5: =VLOOKUP(A5,'APRIL Expired'!A:E,4,FALSE) -> #N/A | F5: =VLOOKUP(A5,'APRIL Expired'!A:E,9,FALSE) -> #REF!
A6: AHI2EK2EBLA8C | B6: Marry Me - The Store - IN | C6: PERFORMANCE + RAPO | D6: 5 | E6: =VLOOKUP(A6,'APRIL Expired'!A:E,4,FALSE) -> #N/A | F6: =VLOOKUP(A6,'APRIL Expired'!A:E,9,FALSE) -> #REF!
A7: AQU3A4KB00ZQV | B7: RUDRAAY ENTERPRISE - IN | C7: PERFORMANCE + RAPO | D7: 4 | E7: =VLOOKUP(A7,'APRIL Expired'!A:E,4,FALSE) -> #N/A | F7: =VLOOKUP(A7,'APRIL Expired'!A:E,9,FALSE) -> #REF!
A8: A3U93ASJOD6B3P | B8: THE FIRE COMPANY - IN | C8: ONLY RAPO | D8: 4 | E8: =VLOOKUP(A8,'APRIL Expired'!A:E,4,FALSE) -> #N/A | F8: =VLOOKUP(A8,'APRIL Expired'!A:E,9,FALSE) -> #REF!
A9: AA1TV72QJ6B8U | B9: TITRI - IN | C9: ONLY RAPO | D9: 4 | E9: =VLOOKUP(A9,'APRIL Expired'!A:E,4,FALSE) -> #N/A | F9: =VLOOKUP(A9,'APRIL Expired'!A:E,9,FALSE) -> #REF!
A10: A13PC6SFMYE124 | B10: SHOPIVAAN - IN | C10: ONLY PERFORMANCE | D10: 4 | E10: =VLOOKUP(A10,'APRIL Expired'!A:E,4,FALSE) -> #N/A | F10: =VLOOKUP(A10,'APRIL Expired'!A:E,9,FALSE) -> #REF!
A11: A196ZJCY6DFAG6 | B11: SAVAYO - IN | C11: ONLY PERFORMANCE | D11: 4 | E11: =VLOOKUP(A11,'APRIL Expired'!A:E,4,FALSE) -> #N/A | F11: =VLOOKUP(A11,'APRIL Expired'!A:E,9,FALSE) -> #REF!
A12: A1FY7MBICOH0M6 | B12: TRUE OPULENCE LIFESTYLE PRIVATE LIMITED - IN | C12: ONLY PERFORMANCE | D12: 4 | E12: =VLOOKUP(A12,'APRIL Expired'!A:E,4,FALSE) -> #N/A | F12: =VLOOKUP(A12,'APRIL Expired'!A:E,9,FALSE) -> #REF!
A13: A1GFLD8QOVMD0K | B13: M/S SINSKARI - IN | C13: ONLY PERFORMANCE | D13: 4 | E13: =VLOOKUP(A13,'APRIL Expired'!A:E,4,FALSE) -> #N/A | F13: =VLOOKUP(A13,'APRIL Expired'!A:E,9,FALSE) -> #REF!
... A50: AUBOR6WACS7SU | B50: MOTHER ORGANIC SB INDIA PRIVATE LIMITED Fashion - IN | C50: NO PERFORMANCE OR RAPO | D50: 4 | E50: =VLOOKUP(A50,'APRIL Expired'!A:E,4,FALSE) -> #N/A | F50: =VLOOKUP(A50,'APRIL Expired'!A:E,9,FALSE) -> #REF!

Sheet Sheet5
A1: Mulberry Living Private Limited - IN | B1: Tazeen | C1: =VLOOKUP(A1,'APRIL Expired'!B:B,1,FALSE) -> #N/A
A2: KOA LUXURY BODY REGIME - IN | B2: Tazeen | C2: =VLOOKUP(A2,'APRIL Expired'!B:B,1,FALSE) -> #N/A
A3: Mea Bloom - IN | B3: Tazeen | C3: =VLOOKUP(A3,'APRIL Expired'!B:B,1,FALSE) -> #N/A
A4: BABYAURA ESSENTIALS PRIVATE LIMITED - IN | B4: Tazeen | C4: =VLOOKUP(A4,'APRIL Expired'!B:B,1,FALSE) -> #N/A
A5: HAPPFIT WELLNESS PVT LTD - IN | B5: Tazeen | C5: =VLOOKUP(A5,'APRIL Expired'!B:B,1,FALSE) -> #N/A
A6: CONSERN PHARMA LIMITED - IN | B6: Tazeen | C6: =VLOOKUP(A6,'APRIL Expired'!B:B,1,FALSE) -> #N/A
A7: MuscleGrid - IN | B7: Tazeen | C7: =VLOOKUP(A7,'APRIL Expired'!B:B,1,FALSE) -> #N/A
A8: UNIGLOBAL DISTRIBUTORS PRIVATE LIMITED - IN | B8: Tazeen | C8: =VLOOKUP(A8,'APRIL Expired'!B:B,1,FALSE) -> #N/A
C9: =VLOOKUP(A9,'APRIL Expired'!B:B,1,FALSE) -> #N/A
A10: AGUANTE - IN | B10: Vaishalini | C10: =VLOOKUP(A10,'APRIL Expired'!B:B,1,FALSE) -> #N/A
A11: Fore noon - IN | B11: Vaishalini | C11: =VLOOKUP(A11,'APRIL Expired'!B:B,1,FALSE) -> #N/A
A12: Armaan limited Collections - IN | B12: Vaishalini | C12: =VLOOKUP(A12,'APRIL Expired'!B:B,1,FALSE) -> #N/A
A13: SAANVIKA BRAND LABS - IN | B13: Vaishalini | C13: =VLOOKUP(A13,'APRIL Expired'!B:B,1,FALSE) -> #N/A
A14: Vaishnavi Agro Masale - IN | B14: Manzar | C14: =VLOOKUP(A14,'APRIL Expired'!B:B,1,FALSE) -> #N/A
A15: Pioneer Hygiene - IN | B15: Manzar | C15: =VLOOKUP(A15,'APRIL Expired'!B:B,1,FALSE) -> #N/A
A16: Kidscave - IN | B16: Manzar | C16: =VLOOKUP(A16,'APRIL Expired'!B:B,1,FALSE) -> #N/A
A17: HIRVA CREATION IN - IN | B17: Manzar | C17: =VLOOKUP(A17,'APRIL Expired'!B:B,1,FALSE) -> #N/A
A18: M-SHIELD - IN | B18: Vaishalini | C18: =VLOOKUP(A18,'APRIL Expired'!B:B,1,FALSE) -> #N/A
C19: =VLOOKUP(A19,'APRIL Expired'!B:B,1,FALSE) -> #N/A
A20: Maruthu valaris and Boomerangs - IN | B20: Dharnesh | C20: =VLOOKUP(A20,'APRIL Expired'!B:B,1,FALSE) -> #N/A
A21: Falconstar - IN | B21: Dharnesh | C21: =VLOOKUP(A21,'APRIL Expired'!B:B,1,FALSE) -> #N/A
A22: Exams First - IN | B22: Dharnesh | C22: =VLOOKUP(A22,'APRIL Expired'!B:B,1,FALSE) -> #N/A
C23: =VLOOKUP(A23,'APRIL Expired'!B:B,1,FALSE) -> #N/A
A24: ShreenathjiExim - IN | B24: Kruti | C24: =VLOOKUP(A24,'APRIL Expired'!B:B,1,FALSE) -> #N/A
A25: DEE VEE COMMUNICATIONS P LTD - IN | B25: Kruti | C25: =VLOOKUP(A25,'APRIL Expired'!B:B,1,FALSE) -> #N/A
A26: U & U Enterprise - IN | B26: Kruti | C26: =VLOOKUP(A26,'APRIL Expired'!B:B,1,FALSE) -> #N/A
A27: ADGAUR GLASSWARE CO. - IN | B27: Kruti | C27: =VLOOKUP(A27,'APRIL Expired'!B:B,1,FALSE) -> #N/A
A28: Water Purifier India - IN | B28: Kruti | C28: =VLOOKUP(A28,'APRIL Expired'!B:B,1,FALSE) -> #N/A
A29: Vkare Bio Sciences Pvt. Ltd. - IN | B29: Kruti | C29: =VLOOKUP(A29,'APRIL Expired'!B:B,1,FALSE) -> #N/A
A30: Asthetika - IN | B30: Kruti | C30: =VLOOKUP(A30,'APRIL Expired'!B:B,1,FALSE) -> #N/A
A31: HEU By Festive Textiles - IN | B31: Kruti | C31: =VLOOKUP(A31,'APRIL Expired'!B:B,1,FALSE) -> #N/A
A32: Ajaayabghar - IN | B32: Kruti | C32: =VLOOKUP(A32,'APRIL Expired'!B:B,1,FALSE) -> #N/A
A33: DECOPULEN - IN | B33: Kruti | C33: =VLOOKUP(A33,'APRIL Expired'!B:B,1,FALSE) -> #N/A
A34: DEHRAN - IN | B34: Kruti | C34: =VLOOKUP(A34,'APRIL Expired'!B:B,1,FALSE) -> #N/A
C35: =VLOOKUP(A35,'APRIL Expired'!B:B,1,FALSE) -> #N/A
C36: =VLOOKUP(A36,'APRIL Expired'!B:B,1,FALSE) -> #N/A
C37: =VLOOKUP(A37,'APRIL Expired'!B:B,1,FALSE) -> #N/A
C38: =VLOOKUP(A38,'APRIL Expired'!B:B,1,FALSE) -> #N/A
C39: =VLOOKUP(A39,'APRIL Expired'!B:B,1,FALSE) -> #N/A
C40: =VLOOKUP(A40,'APRIL Expired'!B:B,1,FALSE) -> #N/A
...

Sheet f17-11f0-a88f-ed1746cad0d8-stor
A1: connectedOn | B1: accountId | C1: storeName | D1: performance | E1: Rapo | G1: status | H1: amazonAdsConnected | I1: amazonSPConnected | J1: isV2OnBoardingDone | K1: am | L1: score | M1: campaignLaunched | N1: syncProgress | O1: totalRecommendations | P1: appliedRecommendations | Q1: recommendationsAppliedBySeller | R1: autopilotCoverage | S1: team | T1: email | U1: mobile | V1: subscriptionStatus | W1: amazonElevate | X1: week | Y1: country | Z1: automation | AA1: adSpendAligned | AB1: adSpendUpdatedBy | AC1: auditReportSharedBy | AD1: enabledCampaigns | AE1: autopilotEnabled | AF1: adSpendAlignedFrom | AG1: adSpendAlignedTill | AH1: isTechMStore
A2: Thu Sep 25 2025 19:53:27 GMT+0530 (India Standard Time) | B2: A20ABCUM81YT27 | C2: AsmaZara Skin Essentials - IN | D2: P3 | E2: Yes | F2: #N/A | G2: active | H2: TRUE | I2: TRUE | J2: TRUE | K2: Anindya Mandal | L2: 41 | M2: 0 | N2: 100 | R2: 0 | S2: POD-Sanjay | T2: info.asmazara@gmail.com | U2: +918095340640 | V2: trial | W2: TRUE | X2: 4 | Z2: auto | AA2: 0 | AB2: USER | AC2: AM | AD2: 0 | AE2: -1 | AH2: FALSE
A3: Thu Sep 25 2025 13:26:26 GMT+0530 (India Standard Time) | B3: A1YJPQA5XOWSJ4 | C3: CREATIVELY UNIQUE-(DCONSUMERI MEDIATECH PRIVATE LIMITED) - IN | D3: P3 | F3: #N/A | G3: active | H3: TRUE | I3: FALSE | L3: 30 | M3: 0 | N3: 100 | R3: 0 | T3: thecreativelyunique@gmail.com | V3: trial | W3: TRUE | X3: 4 | Z3: auto | AA3: 0 | AB3: USER | AD3: 0 | AE3: -1 | AH3: FALSE
A4: Thu Sep 25 2025 13:08:28 GMT+0530 (India Standard Time) | B4: A3BV1VBHMHIT74 | C4: Eiti - IN | D4: P0 | E4: No | F4: #N/A | G4: active | H4: TRUE | I4: TRUE | J4: TRUE | K4: Syed Yaseen | L4: 56 | M4: 6 | N4: 100 | R4: 100 | S4: POD-Sanjay | T4: sales.ecomonline@gmail.com | U4: +918871743681 | V4: trial | W4: FALSE | X4: 4 | Z4: auto | AA4: 0 | AB4: USER | AC4: AM | AD4: 1 | AE4: 1 | AH4: FALSE
A5: Thu Sep 25 2025 11:53:07 GMT+0530 (India Standard Time) | B5: A1949H1AZUQGGS | C5: Mizi - IN | D5: P3 | F5: #N/A | G5: active | H5: TRUE | I5: FALSE | L5: 26 | M5: 0 | N5: 100 | R5: 0 | T5: mizicart@gmail.com | V5: trial | W5: TRUE | X5: 4 | Z5: auto | AA5: 0 | AB5: USER | AD5: 131 | AE5: 0 | AH5: FALSE
A6: Thu Sep 25 2025 11:35:27 GMT+0530 (India Standard Time) | B6: AEDMW67MJCYOU | C6: Drapes De Dzire - IN | D6: P0 | F6: #N/A | G6: active | H6: TRUE | I6: TRUE | J6: TRUE | K6: Eshwar | L6: 52 | M6: 4 | N6: 100 | R6: 50 | S6: POD-Sanjay | T6: sellersupport@drapesdedzire.com | U6: +919880535345 | V6: trial | W6: FALSE | X6: 4 | Z6: auto | AA6: 0 | AB6: USER | AC6: AM | AD6: 2 | AE6: 1 | AH6: FALSE
A7: Thu Sep 25 2025 11:31:45 GMT+0530 (India Standard Time) | B7: A2DZNTL3BEZ58P | C7: Skarline Ventures - IN | D7: P0 | E7: No | F7: #N/A | G7: active | H7: TRUE | I7: TRUE | J7: TRUE | K7: Gourav Haldar | L7: 56 | M7: 2 | N7: 100 | R7: 50 | S7: POD-Chamath | T7: skarlineventures@gmail.com | U7: +918489778088 | V7: trial | W7: FALSE | X7: 4 | Z7: auto | AA7: 0 | AB7: USER | AC7: AM | AD7: 4 | AE7: 2 | AH7: FALSE
A8: Thu Sep 25 2025 11:18:49 GMT+0530 (India Standard Time) | B8: A271760IXV2XZ5 | C8: UDAY CHEMICAL WORKS HATHRAS - IN | D8: P3 | E8: No | F8: #N/A | G8: active | H8: TRUE | I8: TRUE | K8: Gourav Haldar | L8: 67 | M8: 2 | N8: 100 | R8: 100 | S8: POD-Chamath | T8: harshitagrawal599@gmail.com | V8: trial | W8: FALSE | X8: 4 | Z8: auto | AA8: 0 | AB8: USER | AC8: AM | AD8: 2 | AE8: 2 | AH8: FALSE
A9: Wed Sep 24 2025 21:32:37 GMT+0530 (India Standard Time) | B9: A2K365TW6XBY7X | C9: WEBMART - IN | D9: P0 | F9: #N/A | G9: active | H9: TRUE | I9: TRUE | J9: TRUE | K9: Eshwar | L9: 45 | M9: 0 | N9: 100 | R9: 0 | S9: POD-Sanjay | T9: contact.galaxyrise@gmail.com | U9: +918368865192 | V9: trial | W9: TRUE | X9: 4 | Z9: auto | AA9: 0 | AB9: USER | AC9: AM | AD9: 5 | AE9: 0 | AH9: FALSE
A10: Wed Sep 24 2025 17:59:48 GMT+0530 (India Standard Time) | B10: A3J4RWKX1K5P9M | C10: Shiv Shambhu Enterprises - IN | D10: P0 | E10: No | F10: #N/A | G10: active | H10: TRUE | I10: TRUE | J10: TRUE | K10: Syed Tabrez | L10: 41 | M10: 4 | N10: 100 | R10: 0 | S10: POD-Chamath | T10: shivshambhuenterprises55@gmail.com | U10: +919166662950 | V10: trial | W10: FALSE | X10: 4 | Z10: auto | AA10: 0 | AB10: USER | AC10: AM | AD10: 0 | AE10: -1 | AH10: FALSE
A11: Wed Sep 24 2025 17:17:36 GMT+0530 (India Standard Time) | B11: A28MJD4ME470ZF | C11: EPICURA GLOBAL - IN | D11: P0 | E11: No | F11: #N/A | G11: active | H11: TRUE | I11: TRUE | J11: TRUE | K11: Syed Tabrez | L11: 56 | M11: 3 | N11: 100 | R11: 0 | S11: POD-Chamath | T11: zingoraonline@gmail.com | U11: +919587864866 | V11: trial | W11: FALSE | X11: 4 | Z11: auto | AA11: 0 | AB11: USER | AC11: AM | AD11: 1 | AE11: 0 | AH11: FALSE
A12: Wed Sep 24 2025 16:19:44 GMT+0530 (India Standard Time) | B12: A1D105RGLX852N | C12: Tanish Herbs - IN | D12: P0 | E12: Yes | F12: #N/A | G12: active | H12: TRUE | I12: TRUE | J12: TRUE | K12: Syed Tabrez | L12: 56 | M12: 4 | N12: 100 | R12: 100 | S12: POD-Chamath | T12: tanishherbs@gmail.com | U12: +919840836999 | V12: trial | W12: FALSE | X12: 4 | Z12: manual | AA12: 0 | AB12: USER | AC12: AM | AD12: 2 | AE12: 2 | AH12: FALSE
A13: Wed Sep 24 2025 15:43:39 GMT+0530 (India Standard Time) | B13: A3N9KNIJ9HBA2Z | C13: WE_ADOS - IN | D13: P0 | E13: Yes | F13: #N/A | G13: active | H13: TRUE | I13: TRUE | J13: TRUE | K13: Syed Tabrez | L13: 67 | M13: 5 | N13: 100 | R13: 75 | S13: POD-Chamath | T13: zerodegreefashion@yahoo.in | U13: +919820211373 | V13: trial | W13: FALSE | X13: 4 | Z13: auto | AA13: 0 | AB13: USER | AC13: AM | AD13: 4 | AE13: 3 | AH13: FALSE
A14: Wed Sep 24 2025 15:35:07 GMT+0530 (India Standard Time) | B14: A2BDH9QXAZ4X8U | C14: Woot Hoot, India - IN | D14: P0 | E14: Yes | F14: #N/A | G14: active | H14: TRUE | I14: TRUE | J14: TRUE | K14: Syed Tabrez | L14: 60 | M14: 7 | N14: 100 | R14: 67 | S14: POD-Chamath | T14: sales@ezchip.in | U14: +919960832807 | V14: trial | W14: FALSE | X14: 4 | Z14: auto | AA14: 0 | AB14: USER | AC14: AM | AD14: 6 | AE14: 4 | AH14: FALSE
A15: Wed Sep 24 2025 15:28:45 GMT+0530 (India Standard Time) | B15: A2MFWWVVTETT2O | C15: BLACKBULL INDIA - IN | D15: P0 | F15: #N/A | G15: active | H15: TRUE | I15: TRUE | J15: TRUE | K15: Eshwar | L15: 41 | M15: 5 | N15: 100 | R15: 0 | S15: POD-Sanjay | T15: technologyblackbull@gmail.com | U15: +919330171036 | V15: trial | W15: FALSE | X15: 4 | Z15: auto | AA15: 0 | AB15: USER | AC15: AM | AD15: 0 | AE15: -1 | AH15: FALSE
A16: Wed Sep 24 2025 14:16:13 GMT+0530 (India Standard Time) | B16: A3ULMVZMHS99GY | C16: FIT N FURNISH HUB - IN | D16: P2 | F16: #N/A | G16: active | H16: TRUE | I16: FALSE | L16: 26 | M16: 0 | N16: 100 | R16: 0 | T16: fitnfurnishhub@gmail.com | V16: trial | W16: TRUE | X16: 4 | Z16: auto | AA16: 0 | AB16: USER | AD16: 1 | AE16: 0 | AH16: FALSE
A17: Wed Sep 24 2025 12:39:50 GMT+0530 (India Standard Time) | B17: ATD3MNX0KWZI8 | C17: shrijan innovation - IN | D17: P0 | E17: No | F17: #N/A | G17: active | H17: TRUE | I17: TRUE | J17: TRUE | K17: Syed Tabrez | L17: 56 | M17: 6 | N17: 100 | R17: 100 | S17: POD-Chamath | T17: starinterior9@gmail.com | U17: +918446900370 | V17: trial | W17: FALSE | X17: 4 | Z17: manual | AA17: 0 | AB17: USER | AC17: AM | AD17: 4 | AE17: 4 | AH17: FALSE
A18: Wed Sep 24 2025 11:40:54 GMT+0530 (India Standard Time) | B18: A392PRDNEHTQRJ | C18: TWIN FLAMES | D18: P1 | F18: #N/A | G18: active | H18: TRUE | I18: TRUE | J18: TRUE | K18: Eshwar | L18: 41 | M18: 5 | N18: 100 | R18: 0 | S18: POD-Sanjay | T18: hello@twinflames.in | U18: +918910863367 | V18: trial | W18: FALSE | X18: 4 | Z18: auto | AA18: 0 | AB18: USER | AC18: AM | AD18: 0 | AE18: -1 | AH18: FALSE
A19: Wed Sep 24 2025 11:33:40 GMT+0530 (India Standard Time) | B19: A3URYXFQXNEJ1L | C19: BRANDSHOPS INC - IN | D19: P3 | F19: #N/A | G19: active | H19: TRUE | I19: TRUE | J19: TRUE | K19: Eshwar | L19: 49 | M19: 0 | N19: 100 | R19: 0 | S19: POD-Sanjay | T19: brandshopsinc@gmail.com | U19: +919711565507 | V19: trial | W19: TRUE | X19: 4 | Z19: auto | AA19: 0 | AB19: USER | AC19: AM | AD19: 10 | AE19: 0 | AH19: FALSE
A20: Tue Sep 23 2025 15:43:39 GMT+0530 (India Standard Time) | B20: A2HHIPJT8WYHST | C20: Krypton Consumer Electricals - IN | D20: P0 | E20: Yes | F20: #N/A | G20: active | H20: TRUE | I20: TRUE | J20: TRUE | K20: Abhilash V | L20: 56 | M20: 6 | N20: 100 | R20: 100 | S20: POD-Chamath | T20: salesenquiry@krypton.co.in | U20: +919971691109 | V20: trial | W20: FALSE | X20: 4 | Z20: auto | AA20: 0 | AB20: USER | AC20: AM | AD20: 3 | AE20: 3 | AH20: FALSE
A21: Tue Sep 23 2025 13:15:53 GMT+0530 (India Standard Time) | B21: ATOHD233WJUAW | C21: Sugar Apple - IN | D21: P3 | E21: No | F21: #N/A | G21: active | H21: TRUE | I21: TRUE | J21: TRUE | K21: Ved Prakash Kondaboiena | L21: 60 | M21: 5 | N21: 100 | R21: 100 | S21: POD-Chamath | T21: connect@urrja.in | U21: +918697559020 | V21: trial | W21: FALSE | X21: 4 | Z21: auto | AA21: 0 | AB21: USER | AC21: AM | AD21: 5 | AE21: 5 | AH21: FALSE
A22: Sun Sep 21 2025 22:00:11 GMT+0530 (India Standard Time) | B22: A2NFORKRW4XHK3 | C22: Alchemy Tradex - IN | D22: P0 | E22: Yes | F22: #N/A | G22: active | H22: TRUE | I22: TRUE | J22: TRUE | K22: Anindya Mandal | L22: 56 | M22: 2 | N22: 100 | R22: 40 | S22: POD-Sanjay | T22: smoyade41@gmail.com | U22: +919584209994 | V22: trial | W22: TRUE | X22: 4 | Z22: auto | AA22: 0 | AB22: USER | AC22: AM | AD22: 5 | AE22: 2 | AH22: FALSE
A23: Sat Sep 20 2025 18:00:53 GMT+0530 (India Standard Time) | B23: A1E2SNORL77B2Z | C23: JOLIEZZA - US | D23: P3 | F23: #N/A | G23: active | H23: FALSE | I23: TRUE | J23: TRUE | L23: 23 | M23: 2 | N23: 100 | R23: 0 | T23: joliezzaskincare@gmail.com | U23: +919541638355 | V23: trial | X23: 3 | Z23: auto | AA23: 0 | AB23: USER | AC23: AM | AD23: 0 | AE23: -1 | AH23: FALSE
A24: Tue Sep 16 2025 13:33:04 GMT+0530 (India Standard Time) | B24: AJYSJBYKM5AIC | C24: NEXTBRIDGE INTERNATIONAL PRIVATE LIMITED - IN | D24: P0 | E24: No | F24: #N/A | G24: active | H24: TRUE | I24: TRUE | K24: Anindya Mandal | L24: 41 | M24: 2 | N24: 100 | R24: 0 | S24: POD-Sanjay | T24: connect@nextbridgeinternational.com | V24: trial | W24: FALSE | X24: 5 | Z24: auto | AA24: 0 | AB24: USER | AC24: AM | AD24: 1 | AE24: 0 | AH24: FALSE
A25: Tue Sep 16 2025 13:02:46 GMT+0530 (India Standard Time) | B25: A18S33BOOT5V4P | C25: TIKKOST TECHNOLOGIES - IN | D25: P3 | F25: #N/A | G25: active | H25: TRUE | I25: FALSE | L25: 26 | M25: 0 | N25: 100 | R25: 0 | T25: tikos3242@gmail.com | V25: trial | W25: TRUE | X25: 5 | Z25: auto | AA25: 0 | AB25: USER | AD25: 3 | AE25: 0 | AH25: FALSE
A26: Mon Sep 15 2025 15:21:42 GMT+0530 (India Standard Time) | B26: A1ABQOCQOPA6EP | C26: Varnika Creation Store - IN | D26: P1 | E26: No | F26: #N/A | G26: active | H26: TRUE | I26: TRUE | J26: TRUE | K26: Gourav Haldar | L26: 45 | M26: 3 | N26: 100 | R26: 0 | S26: POD-Chamath | T26: varnikacreation.ecommerce@gmail.com | U26: +917600536162 | V26: trial | W26: FALSE | X26: 5 | Z26: auto | AA26: 420.43 | AB26: USER | AC26: AM | AD26: 4 | AE26: 0 | AF26: 45922 | AG26: 45953 | AH26: FALSE
A27: Fri Sep 12 2025 12:33:48 GMT+0530 (India Standard Time) | B27: A14NGGNR8IT5EP | C27: GFC GARAM MASALA - IN | D27: P1 | E27: No | F27: #N/A | G27: active | H27: TRUE | I27: TRUE | J27: TRUE | K27: Gulshan K | L27: 60 | M27: 2 | N27: 100 | R27: 17 | S27: POD-Chamath | T27: deepakkb54@gmail.com | U27: +919686413915 | V27: trial | W27: TRUE | X27: 6 | Z27: auto | AA27: 12000 | AB27: USER | AC27: AM | AD27: 12 | AE27: 2 | AF27: 45922 | AG27: 45953 | AH27: FALSE
A28: Wed Sep 10 2025 18:52:04 GMT+0530 (India Standard Time) | B28: A2BXW0Y3S27PP3 | C28: Luxury Gift - IN | D28: P2 | E28: No | F28: #N/A | G28: active | H28: TRUE | I28: FALSE | J28: TRUE | K28: Sanjay | L28: 30 | M28: 3 | N28: 100 | R28: 0 | S28: POD-Sanjay | T28: luxurygiftset@gmail.com | U28: +917011906731 | V28: trial | W28: TRUE | X28: 6 | Z28: auto | AA28: 19474.42 | AB28: USER | AC28: AM | AD28: 0 | AE28: -1 | AF28: 45922 | AG28: 45953 | AH28: FALSE
A29: Wed Sep 10 2025 13:05:47 GMT+0530 (India Standard Time) | B29: A1RI9F4KK5MANH | C29: GiftOday - IN | D29: P2 | E29: No | F29: #N/A | G29: active | H29: TRUE | I29: FALSE | J29: TRUE | K29: Sanjay | L29: 30 | M29: 2 | N29: 100 | R29: 0 | S29: POD-Sanjay | T29: giftoday01@gmail.com | U29: +919999558984 | V29: trial | W29: TRUE | X29: 6 | Z29: auto | AA29: 81349.91 | AB29: USER | AC29: AM | AD29: 18 | AE29: 0 | AF29: 45922 | AG29: 45953 | AH29: FALSE
A30: Tue Sep 09 2025 15:38:21 GMT+0530 (India Standard Time) | B30: A11OE7NXKSPFSZ | C30: Flexible bags - IN | D30: P3 | F30: #N/A | G30: active | H30: FALSE | I30: FALSE | L30: 23 | M30: 0 | N30: 100 | R30: 0 | T30: iqbalkhan8328@gmail.com | V30: trial | W30: TRUE | X30: 6 | Z30: auto | AA30: 0 | AB30: USER | AD30: 4 | AE30: 0 | AH30: FALSE
A31: Mon Sep 08 2025 15:46:07 GMT+0530 (India Standard Time) | B31: ENTITY1AP61OT0K5PEO | C31: The Moda India - IN | D31: P2 | E31: No | F31: #N/A | G31: active | H31: TRUE | I31: TRUE | J31: TRUE | K31: Bhargavi | L31: 67 | M31: 4 | N31: 100 | R31: 14 | S31: POD-Sanjay | T31: modafoamandfurnishings@gmail.com | U31: +917869952535 | V31: paid | W31: TRUE | X31: 6 | Z31: auto | AA31: 105907.26 | AB31: USER | AC31: AM | AD31: 30 | AE31: 4 | AF31: 45922 | AG31: 45953 | AH31: FALSE
A32: Wed Sep 03 2025 13:23:33 GMT+0530 (India Standard Time) | B32: A31FX0UEY1G6W6 | C32: A.A Oil Mill - IN | D32: P3 | F32: #N/A | G32: active | H32: FALSE | I32: TRUE | J32: TRUE | K32: Moupali Mitra | L32: 60 | M32: 2 | N32: 100 | R32: 100 | S32: POD-Sanjay | T32: cc.aaoilmill@gmail.com | U32: +916369819805 | V32: trial | W32: TRUE | X32: 1 | Z32: auto | AA32: 0 | AB32: USER | AC32: AM | AD32: 3 | AE32: 3 | AH32: FALSE
A33: Tue Sep 02 2025 18:11:04 GMT+0530 (India Standard Time) | B33: AU6PVIBMT67OS | C33: SOBO CONSUMER - IN | D33: P1 | E33: No | F33: #N/A | G33: active | H33: FALSE | I33: TRUE | J33: TRUE | K33: Bhargavi | L33: 49 | M33: 2 | N33: 100 | R33: 0 | S33: POD-Sanjay | T33: soboconsumer@gmail.com | U33: +917208522848 | V33: trial | W33: TRUE | X33: 1 | Z33: auto | AA33: 0 | AB33: USER | AC33: AM | AD33: 8 | AE33: 0 | AH33: FALSE
A34: Tue Sep 02 2025 12:42:44 GMT+0530 (India Standard Time) | B34: A1ODGJZBFLB2KD | C34: TOI SHOP - IN | D34: P3 | F34: #N/A | G34: active | H34: FALSE | I34: TRUE | J34: TRUE | K34: Moupali Mitra | L34: 67 | M34: 0 | N34: 100 | R34: 88 | S34: POD-Sanjay | T34: saiyed1m1@gmail.com | U34: +919558301397 | V34: trial | W34: TRUE | X34: 2 | Z34: auto | AA34: 0 | AB34: USER | AC34: AM | AD34: 8 | AE34: 7 | AH34: FALSE
A35: Mon Sep 01 2025 18:21:27 GMT+0530 (India Standard Time) | B35: A38H1A68423WTN | C35: KHODIYAR SALES.. - IN | D35: P3 | F35: #N/A | G35: active | H35: FALSE | I35: FALSE | J35: TRUE | K35: Shubhangi Singh | L35: 52 | M35: 2 | N35: 100 | R35: 100 | S35: POD-Sanjay | T35: mangukiya4896@gmail.com | U35: +917574945908 | V35: trial | W35: FALSE | X35: 0 | Z35: auto | AA35: 0 | AB35: USER | AC35: AM | AD35: 4 | AE35: 4 | AH35: FALSE
A36: Mon Sep 01 2025 17:58:11 GMT+0530 (India Standard Time) | B36: A2MKY7YFRI6DJX | C36: BAHUCHARAJI CREATION - IN | D36: P2 | F36: #N/A | G36: active | H36: FALSE | I36: FALSE | L36: 30 | M36: 0 | N36: 100 | R36: 0 | T36: vavadiyakrish102@gmail.com | U36: +919054272477 | V36: trial | W36: FALSE | X36: 6 | Z36: auto | AA36: 0 | AB36: USER | AD36: 0 | AE36: -1 | AH36: FALSE
A37: Mon Sep 01 2025 15:00:51 GMT+0530 (India Standard Time) | B37: AOU8JGFXGCMKQ | C37: KEDAR ENTERPRISE ® - IN | D37: P3 | E37: No | F37: #N/A | G37: active | H37: FALSE | I37: FALSE | J37: TRUE | K37: Bhargavi | L37: 63 | M37: 6 | N37: 100 | R37: 88 | S37: POD-Sanjay | T37: kedarenterprise24@gmail.com | U37: +919824524496 | V37: trial | W37: TRUE | X37: 2 | Z37: auto | AA37: 0 | AB37: USER | AC37: AM | AD37: 16 | AE37: 14 | AH37: FALSE
A38: Sat Aug 30 2025 12:19:31 GMT+0530 (India Standard Time) | B38: A2JJUB4HH5OBDC | C38: Pranjal Gems - IN | D38: P2 | E38: No | F38: #N/A | G38: active | H38: TRUE | I38: FALSE | J38: TRUE | K38: Gulshan K | L38: 41 | M38: 0 | N38: 100 | R38: 96 | S38: POD-Chamath | T38: pranjalgems@gmail.com | U38: +917023818175 | V38: trial | W38: TRUE | X38: 8 | Z38: auto | AA38: 0 | AB38: USER | AC38: AM | AD38: 48 | AE38: 46 | AH38: FALSE
A39: Fri Aug 29 2025 16:54:35 GMT+0530 (India Standard Time) | B39: A35AP1DRYBA6W6 | C39: BharatVolt - IN | D39: P1 | E39: No | F39: #N/A | G39: active | H39: FALSE | I39: TRUE | J39: TRUE | K39: Preeti S Bingoli | L39: 23 | M39: 2 | N39: 100 | R39: 0 | S39: POD-Sanjay | T39: marketing@emplworld.in | U39: +919041142244 | V39: trial | W39: FALSE | X39: 3 | Z39: manual | AA39: 0 | AB39: USER | AC39: AM | AD39: 0 | AE39: -1 | AH39: FALSE
A40: Fri Aug 29 2025 10:29:23 GMT+0530 (India Standard Time) | B40: A3J1ZEO3RQ0CYG | C40: sharas enterprise - IN | D40: P3 | F40: #N/A | G40: active | H40: TRUE | I40: FALSE | L40: 26 | M40: 0 | N40: 100 | R40: 0 | T40: logesh@profitstory.ai | V40: trial | X40: 8 | Z40: auto | AA40: 0 | AB40: USER | AD40: 12 | AE40: 0 | AH40: FALSE
...
